Workbook

Sheet Daily
A1: Date | B1: ihsg
A2: 43467 | B2: 6181.175
A3: 43468 | B3: 6221.01
A4: 43469 | B4: 6274.54
A5: 43472 | B5: 6287.224
A6: 43473 | B6: 6262.847
A7: 43474 | B7: 6272.238
A8: 43475 | B8: 6328.714
A9: 43476 | B9: 6361.465
A10: 43479 | B10: 6336.116
A11: 43480 | B11: 6408.784
A12: 43481 | B12: 6413.36
A13: 43482 | B13: 6423.78
... A1693: 46021 | B1693: 8646.938

Sheet Monthly
A1: Date | B1: PIT | C1: Income | D1: rsi | E1: ir | F1: puab | G1: ihk | H1: infl
A2: 43466 | B2: =PPh!J2 -> 12.173618 | C2: =PPh!K2 -> 867.53398 | D2: =RSI!B387 -> 218.13388 | E2: ='7DRR'!B71 -> 6 | F2: =RSI!H387 -> 5.81587 | G2: 149.22931 | H2: 2.8236214
A3: 43497 | B3: =PPh!J3 -> 10.225093 | C3: =PPh!K3 -> 728.67539 | D3: =RSI!B388 -> 218.20218 | E3: ='7DRR'!B72 -> 6 | F3: =RSI!H388 -> 5.71962 | G3: 149.10847 | H3: 2.569531
A4: 43525 | B4: =PPh!J4 -> 19.201289 | C4: =PPh!K4 -> 1368.35 | D4: =RSI!B389 -> 230.16174 | E4: ='7DRR'!B73 -> 6 | F4: =RSI!H389 -> 5.92947 | G4: 149.27327 | H4: 2.4815307
A5: 43556 | B5: =PPh!J5 -> 12.16 | C5: =PPh!K5 -> 866.56352 | D5: =RSI!B390 -> 229.34501 | E5: ='7DRR'!B74 -> 6 | F5: =RSI!H390 -> 5.87153 | G5: 149.93246 | H5: 2.833244
A6: 43586 | B6: =PPh!J6 -> 19.08 | C6: =PPh!K6 -> 1359.7066 | D6: =RSI!B391 -> 249.7863 | E6: ='7DRR'!B75 -> 6 | F6: =RSI!H391 -> 5.99352 | G6: 150.9542 | H6: 3.3160352
A7: 43617 | B7: =PPh!J7 -> 13.18 | C7: =PPh!K7 -> 939.25223 | D7: =RSI!B392 -> 233.58105 | E7: ='7DRR'!B76 -> 6 | F7: =RSI!H392 -> 5.77315 | G7: 151.78917 | H7: 3.2817552
A8: 43647 | B8: =PPh!J8 -> 14.04 | C8: =PPh!K8 -> 1000.5388 | D8: =RSI!B393 -> 221.23412 | E8: ='7DRR'!B77 -> 5.75 | F8: =RSI!H393 -> 5.59452 | G8: 152.26159 | H8: 3.3174242
A9: 43678 | B9: =PPh!J9 -> 10.98 | C9: =PPh!K9 -> 782.47265 | D9: =RSI!B394 -> 216.55796 | E9: ='7DRR'!B78 -> 5.5 | F9: =RSI!H394 -> 5.31112 | G9: 152.43737 | H9: 3.4907074
A10: 43709 | B10: =PPh!J10 -> 9.77 | C10: =PPh!K10 -> 696.24388 | D10: =RSI!B395 -> 212.36305 | E10: ='7DRR'!B79 -> 5.25 | F10: =RSI!H395 -> 5.13075 | G10: 152.01988 | H10: 3.3923573
A11: 43739 | B11: =PPh!J11 -> 10.34 | C11: =PPh!K11 -> 736.86404 | D11: =RSI!B396 -> 215.70878 | E11: ='7DRR'!B80 -> 5 | F11: =RSI!H396 -> 4.851 | G11: 152.05283 | H11: 3.1296487
A12: 43770 | B12: =PPh!J12 -> 12.36 | C12: =PPh!K12 -> 880.81621 | D12: =RSI!B397 -> 216.5813 | E12: ='7DRR'!B81 -> 5 | F12: =RSI!H397 -> 4.84991 | G12: 152.27258 | H12: 3.002376
A13: 43800 | B13: =PPh!J13 -> 16.35 | C13: =PPh!K13 -> 1165.1574 | D13: =RSI!B398 -> 235.09791 | E13: ='7DRR'!B82 -> 5 | F13: =RSI!H398 -> 4.88266 | G13: 152.78893 | H13: 2.7180647
... A85: 45992 | B85: =PPh!J85 -> 29.89 | C85: =PPh!K85 -> 2058.1409 | D85: =RSI!B470 -> 231.74724 | E85: ='7DRR'!B154 -> 4.75 | F85: =RSI!H470 -> 4.05892 | G85: 178.96266 | H85: 2.92

Sheet Annual
B1: PIT (Rp tn) | C1: income per capita (Rp mn) | D1: employment (juta) | E1: taxable income (Rp T) | F1: disposable income (Rp T) | G1: national income (Rp T) | H1: PIT/income | I1: PIT/taxable income | J1: income per capita growth
A2: 2019 | B2: 159.86 | C2: =National_income!B47/1000000 -> 42.681403 | D2: 126.51512 | E2: =C2*D2 -> 5399.8428 | F2: =National_income!D47/1000 -> 11500.106 | G2: =National_income!F47/1000 -> 11392.175 | H2: =B2/G2 -> 0.014032439 | I2: =B2/E2 -> 0.029604565
A3: 2020 | B3: 152.34 | C3: =National_income!B48/1000000 -> 42.358683 | D3: 128.45418 | E3: =C3*D3 -> 5441.1501 | F3: =National_income!D48/1000 -> 11504.819 | G3: =National_income!F48/1000 -> 11418.481 | H3: =B3/G3 -> 0.01334153 | I3: =B3/E3 -> 0.027997758 | J3: =C3/C2-1 -> -0.007561145 | K3: =G3/G2-1 -> 0.0023091283
A4: 2021 | B4: 162.11 | C4: =National_income!B49/1000000 -> 46.100282 | D4: 131.05052 | E4: =C4*D4 -> 6041.4661 | F4: =National_income!D49/1000 -> 12660.214 | G4: =National_income!F49/1000 -> 12570.586 | H4: =B4/G4 -> 0.012895978 | I4: =B4/E4 -> 0.026832891 | J4: =C4/C3-1 -> 0.088331333 | K4: =G4/G3-1 -> 0.10089829
A5: 2022 | B5: 183.96651 | C5: =National_income!B50/1000000 -> 52.204437 | D5: 135.29671 | E5: =C5*D5 -> 7063.0887 | F5: =National_income!D50/1000 -> 14479.962 | G5: =National_income!F50/1000 -> 14393.802 | H5: =B5/G5 -> 0.012780953 | I5: =B5/E5 -> 0.026046185 | J5: =C5/C4-1 -> 0.13241036 | K5: =G5/G4-1 -> 0.14503831
A6: 2023 | B6: 213.81016 | C6: =National_income!B51/1000000 -> 54.362521 | D6: 139.85238 | E6: =C6*D6 -> 7602.7278 | F6: =National_income!D51/1000 -> 15232.602 | G6: =National_income!F51/1000 -> 15150.628 | H6: =B6/G6 -> 0.014112297 | I6: =B6/E6 -> 0.028122822 | J6: =C6/C5-1 -> 0.041339096 | K6: =G6/G5-1 -> 0.052579942
A7: 2024 | B7: 257.18 | C7: =National_income!B52/1000000 -> 57.171002 | D7: 144.642 | E7: =C7*D7 -> 8269.3284 | F7: =National_income!D52/1000 -> 16194.305 | G7: =National_income!F52/1000 -> 16099.571 | H7: =B7/G7 -> 0.015974338 | I7: =B7/E7 -> 0.03110047 | J7: =C7/C6-1 -> 0.051662086 | K7: =G7/G6-1 -> 0.062633958
A8: 2025 | B8: 248.2 | C8: =C7*(1+J8) -> 60.057679 | D8: 146.54226 | E8: =C8*D8 -> 8800.9882 | F8: =National_income!D53/1000 -> 0 | G8: =G7*(1+K8) -> 17090.35 | H8: =B8/G8 -> 0.014522816 | I8: =B8/E8 -> 0.028201378 | J8: =_xlfn.FORECAST.LINEAR(J7,J6:J7,J5:J6) -> 0.050491968 | K8: =_xlfn.FORECAST.LINEAR(K7,K6:K7,K5:K6) -> 0.061540674

Sheet PPh
A1: Date | B1: Year | C1: PPh_nonmigas | D1: PPh Badan | E1: PPh Ps 21 | F1: PPh Ps 21_flow APBN KITA | G1: PPh Ps 25/29 Personal | H1: PIT_ytd | I1: Share PIT to PPh nonmigas | J1: PIT_flow | K1: income
A2: 43466 | B2: =YEAR(A2) -> 2019 | C2: 49.8784 | H2: =AVERAGE(I$4:I$13)*C2 -> 12.173618 | J2: =H2 -> 12.173618 | K2: =J2*(1/Annual!H$2) -> 867.53398
A3: 43497 | B3: =YEAR(A3) -> 2019 | C3: 91.7732 | H3: =AVERAGE(I$4:I$13)*C3 -> 22.398711 | J3: =H3-H2 -> 10.225093 | K3: =J3*(1/Annual!H$2) -> 728.67539
A4: 43525 | B4: =YEAR(A4) -> 2019 | C4: 142.815 | E4: 35.1 | G4: 6.5 | H4: =E4+G4 -> 41.6 | I4: =H4/C4 -> 0.29128593 | J4: =H4-H3 -> 19.201289 | K4: =J4*(1/Annual!H$2) -> 1368.35
A5: 43556 | B5: =YEAR(A5) -> 2019 | C5: 232.731 | E5: 46.47 | G5: 7.29 | H5: =E5+G5 -> 53.76 | I5: =H5/C5 -> 0.2309963 | J5: =H5-H4 -> 12.16 | K5: =J5*(1/Annual!H$2) -> 866.56352
A6: 43586 | B6: =YEAR(A6) -> 2019 | C6: 295.4943 | E6: 65.22 | G6: 7.62 | H6: =E6+G6 -> 72.84 | I6: =H6/C6 -> 0.24650222 | J6: =H6-H5 -> 19.08 | K6: =J6*(1/Annual!H$2) -> 1359.7066
A7: 43617 | B7: =YEAR(A7) -> 2019 | C7: 347.2683 | E7: 78.08 | G7: 7.94 | H7: =E7+G7 -> 86.02 | I7: =H7/C7 -> 0.24770473 | J7: =H7-H6 -> 13.18 | K7: =J7*(1/Annual!H$2) -> 939.25223
A8: 43647 | B8: =YEAR(A8) -> 2019 | C8: 404.537 | E8: 91.56 | G8: 8.5 | H8: =E8+G8 -> 100.06 | I8: =H8/C8 -> 0.2473445 | J8: =H8-H7 -> 14.04 | K8: =J8*(1/Annual!H$2) -> 1000.5388
A9: 43678 | B9: =YEAR(A9) -> 2019 | C9: 455.234 | E9: 102.13 | G9: 8.91 | H9: =E9+G9 -> 111.04 | I9: =H9/C9 -> 0.24391851 | J9: =H9-H8 -> 10.98 | K9: =J9*(1/Annual!H$2) -> 782.47265
A10: 43709 | B10: =YEAR(A10) -> 2019 | C10: 503.2506 | E10: 111.45 | G10: 9.36 | H10: =E10+G10 -> 120.81 | I10: =H10/C10 -> 0.24005933 | J10: =H10-H9 -> 9.77 | K10: =J10*(1/Annual!H$2) -> 696.24388
A11: 43739 | B11: =YEAR(A11) -> 2019 | C11: 556.6181 | E11: 121.27 | G11: 9.88 | H11: =E11+G11 -> 131.15 | I11: =H11/C11 -> 0.23561936 | J11: =H11-H10 -> 10.34 | K11: =J11*(1/Annual!H$2) -> 736.86404
A12: 43770 | B12: =YEAR(A12) -> 2019 | C12: 615.7718 | E12: 133.17 | G12: 10.34 | H12: =E12+G12 -> 143.51 | I12: =H12/C12 -> 0.23305712 | J12: =H12-H11 -> 12.36 | K12: =J12*(1/Annual!H$2) -> 880.81621
A13: 43800 | B13: =YEAR(A13) -> 2019 | C13: 713.1154 | E13: 148.63 | G13: 11.23 | H13: =E13+G13 -> 159.86 | I13: =H13/C13 -> 0.22417129 | J13: =H13-H12 -> 16.35 | K13: =J13*(1/Annual!H$2) -> 1165.1574
A14: 43831 | B14: =YEAR(A14) -> 2020 | C14: 46.3117 | E14: 15.28 | G14: 0.4 | H14: =E14+G14 -> 15.68 | I14: =H14/C14 -> 0.33857535 | J14: =H14 -> 15.68 | K14: =J14*(1/Annual!H$3) -> 1175.2775
A15: 43862 | B15: =YEAR(A15) -> 2020 | C15: 89.3904 | E15: 25.56 | G15: 1.02 | H15: =E15+G15 -> 26.58 | I15: =H15/C15 -> 0.29734737 | J15: =H15-H14 -> 10.9 | K15: =J15*(1/Annual!H$3) -> 816.99776
A16: 43891 | B16: =YEAR(A16) -> 2020 | C16: 137.4756 | E16: 36.58 | G16: 3.08 | H16: =E16+G16 -> 39.66 | I16: =H16/C16 -> 0.28848756 | J16: =H16-H15 -> 13.08 | K16: =J16*(1/Annual!H$3) -> 980.39731
A17: 43922 | B17: =YEAR(A17) -> 2020 | C17: 226.4913 | E17: 48.38 | G17: 7.28 | H17: =E17+G17 -> 55.66 | I17: =H17/C17 -> 0.24574895 | J17: =H17-H16 -> 16 | K17: =J17*(1/Annual!H$3) -> 1199.2628
A18: 43952 | B18: =YEAR(A18) -> 2020 | C18: 264.8324 | E18: 61.96 | G18: 7.81 | H18: =E18+G18 -> 69.77 | I18: =H18/C18 -> 0.26344964 | J18: =H18-H17 -> 14.11 | K18: =J18*(1/Annual!H$3) -> 1057.5999
A19: 43983 | B19: =YEAR(A19) -> 2020 | C19: 312.2529 | E19: 76.32 | G19: 8.23 | H19: =E19+G19 -> 84.55 | I19: =H19/C19 -> 0.27077411 | J19: =H19-H18 -> 14.78 | K19: =J19*(1/Annual!H$3) -> 1107.819
A20: 44013 | B20: =YEAR(A20) -> 2020 | C20: 349.8957 | E20: 86.94 | G20: 8.7 | H20: =E20+G20 -> 95.64 | I20: =H20/C20 -> 0.2733386 | J20: =H20-H19 -> 11.09 | K20: =J20*(1/Annual!H$3) -> 831.23901
A21: 44044 | B21: =YEAR(A21) -> 2020 | C21: 386.2369 | E21: 96.77 | G21: 9.13 | H21: =E21+G21 -> 105.9 | I21: =H21/C21 -> 0.27418406 | J21: =H21-H20 -> 10.26 | K21: =J21*(1/Annual!H$3) -> 769.02725
A22: 44075 | B22: =YEAR(A22) -> 2020 | C22: 418.163 | E22: 106.51 | G22: 9.55 | H22: =E22+G22 -> 116.06 | I22: =H22/C22 -> 0.27754727 | J22: =H22-H21 -> 10.16 | K22: =J22*(1/Annual!H$3) -> 761.53186
A23: 44105 | B23: =YEAR(A23) -> 2020 | C23: 450.6676 | E23: 115.71 | G23: 10 | H23: =E23+G23 -> 125.71 | I23: =H23/C23 -> 0.27894173 | J23: =H23-H22 -> 9.65 | K23: =J23*(1/Annual!H$3) -> 723.30536
A24: 44136 | B24: =YEAR(A24) -> 2020 | C24: 492.568 | E24: 126.25 | G24: 10.51 | H24: =E24+G24 -> 136.76 | I24: =H24/C24 -> 0.27764694 | J24: =H24-H23 -> 11.05 | K24: =J24*(1/Annual!H$3) -> 828.24085
A25: 44166 | B25: =YEAR(A25) -> 2020 | C25: 561.0066 | E25: 140.78 | G25: 11.56 | H25: =E25+G25 -> 152.34 | I25: =H25/C25 -> 0.27154761 | J25: =H25-H24 -> 15.58 | K25: =J25*(1/Annual!H$3) -> 1167.7821
A26: 44197 | B26: =YEAR(A26) -> 2021 | C26: 39.0172 | E26: 14.36 | G26: 0.36 | H26: =E26+G26 -> 14.72 | I26: =H26/C26 -> 0.37726951 | J26: =H26 -> 14.72 | K26: =J26*(1/Annual!H$4) -> 1141.4411
A27: 44228 | B27: =YEAR(A27) -> 2021 | C27: 80.1623 | E27: 24.15 | G27: 0.9 | H27: =E27+G27 -> 25.05 | I27: =H27/C27 -> 0.31249103 | J27: =H27-H26 -> 10.33 | K27: =J27*(1/Annual!H$4) -> 801.02493
A28: 44256 | B28: =YEAR(A28) -> 2021 | C28: 120.7159 | E28: 34.54 | G28: 6.15 | H28: =E28+G28 -> 40.69 | I28: =H28/C28 -> 0.33707242 | J28: =H28-H27 -> 15.64 | K28: =J28*(1/Annual!H$4) -> 1212.7812
A29: 44287 | B29: =YEAR(A29) -> 2021 | C29: 216.2326 | E29: 46.38 | G29: 7.03 | H29: =E29+G29 -> 53.41 | I29: =H29/C29 -> 0.24700253 | J29: =H29-H28 -> 12.72 | K29: =J29*(1/Annual!H$4) -> 986.35403
A30: 44317 | B30: =YEAR(A30) -> 2021 | C30: 257.6981 | E30: 64.65 | G30: 7.58 | H30: =E30+G30 -> 72.23 | I30: =H30/C30 -> 0.28028922 | J30: =H30-H29 -> 18.82 | K30: =J30*(1/Annual!H$4) -> 1459.3697
A31: 44348 | B31: =YEAR(A31) -> 2021 | C31: 303.159 | E31: 76.26 | G31: 8.01 | H31: =E31+G31 -> 84.27 | I31: =H31/C31 -> 0.27797294 | J31: =H31-H30 -> 12.04 | K31: =J31*(1/Annual!H$4) -> 933.62441
A32: 44378 | B32: =YEAR(A32) -> 2021 | C32: 347.5005 | E32: 87.51 | G32: 8.43 | H32: =E32+G32 -> 95.94 | I32: =H32/C32 -> 0.27608593 | J32: =H32-H31 -> 11.67 | K32: =J32*(1/Annual!H$4) -> 904.9333
A33: 44409 | B33: =YEAR(A33) -> 2021 | C33: 390.7919 | E33: 98.99 | G33: 8.94 | H33: =E33+G33 -> 107.93 | I33: =H33/C33 -> 0.2761828 | J33: =H33-H32 -> 11.99 | K33: =J33*(1/Annual!H$4) -> 929.74723
A34: 44440 | B34: =YEAR(A34) -> 2021 | C34: 443.5776 | E34: 108.92 | G34: 9.52 | H34: =E34+G34 -> 118.44 | I34: =H34/C34 -> 0.26701078 | J34: =H34-H33 -> 10.51 | K34: =J34*(1/Annual!H$4) -> 814.98277
A35: 44470 | B35: =YEAR(A35) -> 2021 | C35: 490.7941 | E35: 118.82 | G35: 10.28 | H35: =E35+G35 -> 129.1 | I35: =H35/C35 -> 0.2630431 | J35: =H35-H34 -> 10.66 | K35: =J35*(1/Annual!H$4) -> 826.6143
A36: 44501 | B36: =YEAR(A36) -> 2021 | C36: 554.6561 | E36: 130.52 | G36: 11.04 | H36: =E36+G36 -> 141.56 | I36: =H36/C36 -> 0.25522121 | J36: =H36-H35 -> 12.46 | K36: =J36*(1/Annual!H$4) -> 966.19271
A37: 44531 | B37: =YEAR(A37) -> 2021 | C37: 643.8376 | E37: 149.75 | F37: 14.9 | G37: 12.36 | H37: =E37+G37 -> 162.11 | I37: =H37/C37 -> 0.2517871 | J37: =H37-H36 -> 20.55 | K37: =J37*(1/Annual!H$4) -> 1593.5201
A38: 44562 | B38: =YEAR(A38) -> 2022 | C38: 61.1466 | E38: 18.22 | F38: 18.3 | G38: 0.43 | H38: =E38+G38 -> 18.65 | I38: =H38/C38 -> 0.30500469 | J38: =H38 -> 18.65 | K38: =J38*(1/Annual!H$5) -> 1459.2026
A39: 44593 | B39: =YEAR(A39) -> 2022 | C39: 110.245 | E39: 28.57 | F39: 10.4 | G39: 0.97 | H39: =E39+G39 -> 29.54 | I39: =H39/C39 -> 0.26794866 | J39: =H39-H38 -> 10.89 | K39: =J39*(1/Annual!H$5) -> 852.04914
A40: 44621 | B40: =YEAR(A40) -> 2022 | C40: 172.4425 | E40: 41.02 | F40: 12.4 | G40: 6.95 | H40: =E40+G40 -> 47.97 | I40: =H40/C40 -> 0.27817968 | J40: =H40-H39 -> 18.43 | K40: =J40*(1/Annual!H$5) -> 1441.9895
...

Sheet National_income
A1: =CEIC.LINK("fde0b22e-ddfc-48c1-a6bf-a7b7b9c79390", "Series") -> #NAME? | B1: National Income per Capita: SNA 2008: Annual | C1: National Income per Capita: SNA 1993: 2000 Series: Annual | D1: Disposable Income: SNA 2008 | E1: Disposable Income: SNA 1993: 2000 Series | F1: Gross National Product: SNA 2008: Annual: National Income
A2: Region | B2: Indonesia | C2: Indonesia | D2: Indonesia | E2: Indonesia | F2: Indonesia
A3: Subnational
A4: Frequency | B4: Annual, ending "Dec" of each year | C4: Annual, ending "Dec" of each year | D4: Annual, ending "Dec" of each year | E4: Annual, ending "Dec" of each year | F4: Annual, ending "Dec" of each year
A5: Unit | B5: IDR | C5: IDR | D5: IDR bn | E5: IDR bn | F5: IDR bn
A6: Source | B6: Statistics Indonesia | C6: Statistics Indonesia | D6: Statistics Indonesia | E6: Statistics Indonesia | F6: Statistics Indonesia
A7: Status | B7: Active | C7: Rebased | D7: Active | E7: Rebased | F7: Active
A8: Series ID | B8: 367698317 (DJXBFENAAAABOI) | C8: 13144701 (DARMA) | D8: 372406017 (DAVEAFAKBCACJK) | E8: 314604802 (DADAAAA) | F8: 367698307 (DJXBFENAAAABOH)
A9: SR Code | B9: SR89548777 | C9: SR4838098 | D9: SR95730697 | E9: SR5708549 | F9: SR89548727
A10: Trade Code
A11: Mnemonic
A12: Function Description
A13: First Obs. Date | B13: 40513 | C13: 36861 | D13: 40513 | E13: 36861 | F13: 40513
A14: Last Obs. Date | B14: 45627 | C14: 41609 | D14: 45627 | E14: 41609 | F14: 45627
A15: Last Update Time | B15: 45966 | C15: 44193 | D15: 45966 | E15: 44169 | F15: 45966
A16: Series Remarks | C16: 1. Changed from SNA 1993 to SNA 2008 2. Replacement series ID: 367698317 | E16: 1. Changed from SNA 1993 to SNA 2008 2. Replacement series ID: 372406017
A17: Suggestions | C17: 367698317 | E17: 372406017
A18: Mean | B18: 38456714 | C18: 16588698 | D18: 10239588 | E18: 3909225.8 | F18: 10168874
A19: Variance | B19: 1.1980993e+14 | C19: 8.4573593e+13 | D19: 1.1612013e+13 | E19: 5.6096517e+12 | F19: 1.1482194e+13
A20: Standard Deviation | B20: 10945772 | C20: 9196390.2 | D20: 3407640.4 | E20: 2368470.3 | F20: 3388538.7
A21: Skewness | B21: 0.21347785 | C21: 0.53868668 | D21: 0.27644087 | E21: 0.59356263 | F21: 0.28397154
A22: Kurtosis | B22: -0.91922912 | C22: -1.167724 | D22: -0.91302566 | E22: -1.0607337 | F22: -0.90348043
A23: Coefficient Variation | B23: 0.28462579 | C23: 0.55437684 | D23: 0.33279078 | E23: 0.60586686 | F23: 0.33322653
A24: Min | B24: 21767787 | C24: 6171327.8 | D24: 5214586.1 | E24: 1275928.4 | F24: 5172926
A25: Max | B25: 57171002 | C25: 32476352 | D25: 16194305 | E25: 8119874.2 | F25: 16099571
A26: Median | B26: 38345435 | C26: 14158837 | D26: 10102551 | E26: 3250294.7 | F26: 10042320
A27: No. of Obs | B27: 15 | C27: 14 | D27: 15 | E27: 14 | F27: 15
A28: 36861 | C28: 6171327.8 | E28: 1275928.4
A29: 37226 | C29: 7066148.7 | E29: 1482237.6
A30: 37591 | C30: 7591871.4 | E30: 1616834.9
A31: 37956 | C31: 8155009.4 | E31: 1763080.4
A32: 38322 | C32: 9239222.3 | E32: 2028794.4
A33: 38687 | C33: 11061511 | E33: 2492957.8
A34: 39052 | C34: 13055602 | E34: 2975804.4
A35: 39417 | C35: 15262073 | E35: 3524785
A36: 39783 | C36: 19103240 | E36: 4472543.3
A37: 40148 | C37: 20917535 | E37: 4961430.6
A38: 40513 | B38: 21767787 | C38: 23974407 | D38: 5214586.1 | E38: 5760006.9 | F38: 5172926
A39: 40878 | B39: 24658691 | C39: 27487047 | D39: 6003797.4 | E39: 6688233.2 | F39: 5967173.9
A40: 41244 | B40: 26527004 | C40: 30680428 | D40: 6548817.3 | E40: 7566649.4 | F40: 6510395.3
...

Sheet RSI
A1: =CEIC.LINK("bccd43f9-4a5a-455a-93c6-90fee1e00bb0", "Series") -> #NAME? | B1: Retail Sales Survey: Real Retail Sales Index | C1: Retail Sales Survey: Retailer Expectation: Sales: Next 3 Months | D1: Retail Sales Survey: Retailer Expectation: Sales: Next 6 Months | E1: Retail Sales Survey: Retailer Expectation: General Price: Next 3 Months | F1: Retail Sales Survey: Retailer Expectation: General Price: Next 6 Months | G1: Indonesia Stock Exchange: Index: IDX Composite | H1: Interbank Call Money: 1 Day
A2: Region | B2: Indonesia | C2: Indonesia | D2: Indonesia | E2: Indonesia | F2: Indonesia | G2: Indonesia | H2: Indonesia
A3: Subnational
A4: Frequency | B4: Monthly | C4: Monthly | D4: Monthly | E4: Monthly | F4: Monthly | G4: Monthly | H4: Monthly
A5: Unit | B5: 2010=100 | C5: % | D5: % | E5: % | F5: % | G5: NA | H5: % pa
A6: Source | B6: Bank Indonesia | C6: Bank Indonesia | D6: Bank Indonesia | E6: Bank Indonesia | F6: Bank Indonesia | G6: Exchange Data International Limited | H6: Bank Indonesia
A7: Status | B7: Active | C7: Active | D7: Active | E7: Active | F7: Active | G7: Active | H7: Active
A8: Series ID | B8: 322851702 (DHJAAAA) | C8: 322852502 (DHJAAAK) | D8: 322852602 (DHJAAAL) | E8: 322852902 (DHJAAAO) | F8: 322853002 (DHJAAAP) | G8: 527158177 | H8: 14409201 (DMCA)
A9: SR Code | B9: SR5887893 | C9: SR5887910 | D9: SR5887886 | E9: SR5887895 | F9: SR5887885 | G9: SR215135517 | H9: SR4829525
A10: Trade Code
A11: Mnemonic
A12: Function Description
A13: First Obs. Date | B13: 40179 | C13: 40179 | D13: 40179 | E13: 40179 | F13: 40179 | G13: 41426 | H13: 32540
A14: Last Obs. Date | B14: 45992 | C14: 45962 | D14: 45962 | E14: 45962 | F14: 45962 | G14: 45992 | H14: 45992
A15: Last Update Time | B15: 46034 | C15: 46034 | D15: 46034 | E15: 46034 | F15: 46034 | G15: 46024 | H15: 46024
A16: Series Remarks | B16: [COVID-19-IMPACT] | C16: [COVID-19-IMPACT] | D16: [COVID-19-IMPACT] | E16: [COVID-19-IMPACT] | F16: [COVID-19-IMPACT]
A17: Suggestions
A18: Mean | B18: 183.49683 | C18: 136.72543 | D18: 138.73999 | E18: 142.85582 | F18: 142.1145 | G18: 6012.8528 | H18: 10.303701
A19: Variance | B19: 1836.8306 | C19: 156.5098 | D19: 187.64963 | E19: 173.6273 | F19: 260.35951 | G19: 1002293 | H19: 126.0123
A20: Standard Deviation | B20: 42.858262 | C20: 12.510388 | D20: 13.698527 | E20: 13.176771 | F20: 16.13566 | G20: 1001.1458 | H20: 11.22552
A21: Skewness | B21: -0.76876906 | C21: 0.295035 | D21: 0.16648955 | E21: 0.29732955 | F21: 0.41031026 | G21: 0.12022829 | H21: 3.8153465
A22: Kurtosis | B22: -0.66819591 | C22: -0.79361936 | D22: -0.61343468 | E22: -0.45186314 | F22: -0.85176181 | G22: -0.70240379 | H22: 16.176445
A23: Coefficient Variation | B23: 0.23356405 | C23: 0.091500078 | D23: 0.098735243 | E23: 0.092238255 | F23: 0.11353986 | G23: 0.16650098 | H23: 1.0894649
A24: Min | B24: 90.6 | C24: 112.45791 | D24: 109.58904 | E24: 112.70755 | F24: 110.97754 | G24: 4195.09 | H24: 0.40864
A25: Max | B25: 249.7863 | C25: 167.71357 | D25: 170.69409 | E25: 179.01233 | F25: 177.81045 | G25: 8646.938 | H25: 81.01
A26: Median | B26: 198.39794 | C26: 135.15406 | D26: 137.4359 | E26: 140.36468 | F26: 137.87857 | G26: 5995.62 | H26: 6.28851
A27: No. of Obs | B27: 192 | C27: 191 | D27: 191 | E27: 191 | F27: 191 | G27: 151 | H27: 443
A28: 32540 | H28: 13.52
A29: 32568 | H29: 13.24
A30: 32599 | H30: 12.91
A31: 32629 | H31: 11.08
A32: 32660 | H32: 12.41
A33: 32690 | H33: 11.84
A34: 32721 | H34: 11.67
A35: 32752 | H35: 11.91
A36: 32782 | H36: 11.89
A37: 32813 | H37: 11.8
A38: 32843 | H38: 12.02
A39: 32874 | H39: 9.74
... A278: 40148 | H278: 6.48998
...

Sheet 7DRR
A1: =CEIC.LINK("b5e53f8d-f0f7-45b5-ab75-3e36bd37265a", "Series") -> #NAME? | B1: Policy Rate: Month End: Indonesia: BI-Rate
A2: Region | B2: Indonesia
A3: Subnational
A4: Frequency | B4: Monthly
A5: Unit | B5: % pa
A6: Source | B6: Bank Indonesia
A7: Status | B7: Active
A8: Series ID | B8: 376227237 (DAVEAFAKBCADDZ)
A9: SR Code | B9: SR98288527
A10: Trade Code
A11: Mnemonic
A12: Function Description
A13: First Obs. Date | B13: 42156
A14: Last Obs. Date | B14: 46023
A15: Last Update Time | B15: 46043
A16: Series Remarks | B16: 1. The Bank of Indonesia announced 7 Days Reverse Repo Rate as new policy rate effective August 19th, 2016. 2. For Policy Rate prior to August 2016, please refer to the 1 Month Bank Indonesia Certificates Auction Rate. 3. From 21 December 2023, Bank Indonesia will change the name of its policy rate to BI Rate, replacing the BI 7-Day Reverse Repo. The new name doesn't change the meaning or objectives of the BI-Rates as the monetary policy stance of Bank Indonesia, with operationalisation still referring to Bank Indonesia reverse repo transaction with a tenor of seven days. [COVID-19-IMPACT]
A17: Suggestions
A18: Mean | B18: 5.0074219
A19: Variance | B19: 0.82563346
A20: Standard Deviation | B20: 0.90864375
A21: Skewness | B21: -0.365428
A22: Kurtosis | B22: -1.1751463
A23: Coefficient Variation | B23: 0.1814594
A24: Min | B24: 3.5
A25: Max | B25: 6.25
A26: Median | B26: 5.125
A27: No. of Obs | B27: 128
A28: 42156 | B28: 5.65
A29: 42186 | B29: 5.65
A30: 42217 | B30: 5.75
A31: 42248 | B31: 6.25
A32: 42278 | B32: 6.25
A33: 42309 | B33: 6.25
A34: 42339 | B34: 6.25
A35: 42370 | B35: 5.95
A36: 42401 | B36: 5.7
A37: 42430 | B37: 5.5
A38: 42461 | B38: 5.5
A39: 42491 | B39: 5.5
... A155: 46023 | B155: 4.75

Sheet C quarterly
A1: =CEIC.LINK("85b214b8-c9ba-4e3b-885d-65290fadb6ce", "Series") -> #NAME? | B1: Gross Domestic Product: SNA 2008: 2010p | C1: Gross Domestic Product: SNA 2008: 2010p: Consumption Expenditure: Household | D1: RSI
A2: Region | B2: Indonesia | C2: Indonesia
A3: Subnational
A4: Frequency | B4: Quarterly, ending "Mar, June, Sep, Dec" | C4: Quarterly, ending "Mar, June, Sep, Dec"
A5: Unit | B5: IDR bn | C5: IDR bn
A6: Source | B6: Statistics Indonesia | C6: Statistics Indonesia
A7: Status | B7: Active | C7: Active
A8: Series ID | B8: 365749427 (DJXBFENAAAAAJY) | C8: 365749347 (DJXBFENAAAAAJQ)
A9: SR Code | B9: SR87470257 | C9: SR87470277
A10: Trade Code
A11: Mnemonic | B11: ID.GDP.RL.IDR-BN-Q | C11: ID.GDPFCECHH.RL.IDR-BN-Q
A12: Function Description
A13: First Obs. Date | B13: 40238 | C13: 40238
A14: Last Obs. Date | B14: 45901 | C14: 45901
A15: Last Update Time | B15: 45966 | C15: 45966
A16: Series Remarks | B16: [COVID-19-IMPACT]
A17: Suggestions
A18: Mean | B18: 2495014.5 | C18: 1341144.7
A19: Variance | B19: 2.3699928e+11 | C19: 5.9576554e+10
A20: Standard Deviation | B20: 486825.71 | C20: 244083.09
A21: Skewness | B21: 0.0719328 | C21: -0.010271934
A22: Kurtosis | B22: -0.99122256 | C22: -1.0361663
A23: Coefficient Variation | B23: 0.19511939 | C23: 0.18199609
A24: Min | B24: 1642356.3 | C24: 926097.5
A25: Max | B25: 3444756.7 | C25: 1796800.9
A26: Median | B26: 2508971.9 | C26: 1372141
A27: No. of Obs | B27: 63 | C27: 63
A28: 40238 | B28: 1642356.3 | C28: 926097.5 | D28: =VLOOKUP(A28,RSI!$A$279:$B$470,2,FALSE) -> 94.4
A29: 40330 | B29: 1709132 | C29: 937226.82 | D29: =VLOOKUP(A29,RSI!$A$279:$B$470,2,FALSE) -> 96
A30: 40422 | B30: 1775109.9 | C30: 959649.86 | D30: =VLOOKUP(A30,RSI!$A$279:$B$470,2,FALSE) -> 113.3
A31: 40513 | B31: 1737534.9 | C31: 963088.73 | D31: =VLOOKUP(A31,RSI!$A$279:$B$470,2,FALSE) -> 105.1
A32: 40603 | B32: 1748731.2 | C32: 964261.9 | D32: =VLOOKUP(A32,RSI!$A$279:$B$470,2,FALSE) -> 102.4 | E32: =C32/C28-1 -> 0.041209909 | F32: =D32/D28-1 -> 0.084745763
A33: 40695 | B33: 1816268.2 | C33: 980156.57 | D33: =VLOOKUP(A33,RSI!$A$279:$B$470,2,FALSE) -> 107.8 | E33: =C33/C29-1 -> 0.045805083 | F33: =D33/D29-1 -> 0.12291667
A34: 40787 | B34: 1881849.7 | C34: 1016155.4 | D34: =VLOOKUP(A34,RSI!$A$279:$B$470,2,FALSE) -> 106.6 | E34: =C34/C30-1 -> 0.058881371 | F34: =D34/D30-1 -> -0.05913504
A35: 40878 | B35: 1840786.2 | C35: 1016714.7 | D35: =VLOOKUP(A35,RSI!$A$279:$B$470,2,FALSE) -> 115.7 | E35: =C35/C31-1 -> 0.055681277 | F35: =D35/D31-1 -> 0.10085633
A36: 40969 | B36: 1855580.2 | C36: 1017752.4 | D36: =VLOOKUP(A36,RSI!$A$279:$B$470,2,FALSE) -> 115.18021 | E36: =C36/C32-1 -> 0.055472989 | F36: =D36/D32-1 -> 0.12480671
A37: 41061 | B37: 1929018.7 | C37: 1034180.1 | D37: =VLOOKUP(A37,RSI!$A$279:$B$470,2,FALSE) -> 123.1922 | E37: =C37/C33-1 -> 0.055117297 | F37: =D37/D33-1 -> 0.14278479
A38: 41153 | B38: 1993632.3 | C38: 1071689.6 | D38: =VLOOKUP(A38,RSI!$A$279:$B$470,2,FALSE) -> 127.05198 | E38: =C38/C34-1 -> 0.05465135 | F38: =D38/D34-1 -> 0.1918572
A39: 41244 | B39: 1948852.2 | C39: 1072165.4 | D39: =VLOOKUP(A39,RSI!$A$279:$B$470,2,FALSE) -> 133.15868 | E39: =C39/C35-1 -> 0.054539104 | F39: =D39/D35-1 -> 0.15089611
A40: 41334 | B40: 1958395.5 | C40: 1075566.2 | D40: =VLOOKUP(A40,RSI!$A$279:$B$470,2,FALSE) -> 125.87523 | E40: =C40/C36-1 -> 0.056805377 | F40: =D40/D36-1 -> 0.092854705
...
